Workbook
Name Indicatore_on_off: Governo!$C$65

Sheet PdR 5-2013
C7: I campi di colore verde sono gli unici compilabili. Per maggiori informazioni per la corretta compilazione fare riferimento alla Prassi di Riferimento UNI/PdR 5:2013
C12: Comune di
C16: compilazione a cura di
C18: settore di appartenenza
C20: recapito mail
C22: recapito telefonico

Sheet Governo
A1: PROCESSI DI GOVERNO
C3: Indicatore G.1 | D3: Autonomia Finanziaria
C4: Evidenzia in quale quota l'amministrazione locale faccia leva sul prelievo tributario (imposte, tasse ed altri tributi, e sulle entrate extratributarie (proventi dei servizi pubblici locale, proventi patrimoniali, utili di aziende partecipate o controllate) per procurari le entrate di parte corrente
C6: entrate tributarie (TitoloI) | D6: entrate extratributarie (Titolo II+III) | E6: Totale entrate | F6: G.1
C7: 8683561.4 | D7: 4180143.2 | E7: 15909375 | F7: =(C7+D7)/E7 -> 0.80856126
C9: Note:
C13: Indicatore G.2 | D13: Velocotà di riscossione annua
C14: Indica l'efficienza di un'amministrazione locale, indica la sua capacità di realizzare i crediti nell'anno di Competenza
C16: Riscossioni Titolo I | D16: Riscossioni Titolo III | E16: Accertamenti Titolo I | F16: Accertamenti Titolo III | G16: G.2
C17: 90 | D17: 90 | E17: 100 | F17: 100 | G17: =(C17+D17)/(E17+F17) -> 0.9
C19: Note:
C24: Indicatore G.3 | D24: Efficacia di gestione del Bilancio
C25: Evidenzia la capacità di previsione dell'amministrazione locale misurando lo scostamento tra quanto pianificato e quanto rendicontato alla fine del periodo di riferimento.
C27: Bilancio di Previsione | D27: Rendiconto | E27: G.3
A28: ENTRATE | B28: Tit. I | C28: 100 | D28: 90 | E28: =IF(C28=D28,"=1",IF(C28<D28,"<1",">1")) -> >1
B29: Tit. II | C29: 10 | D29: 11 | E29: =IF(C29=D29,"=1",IF(C29<D29,"<1",">1")) -> <1
B30: Tit. III | C30: 11 | D30: 9 | E30: =IF(C30=D30,"=1",IF(C30<D30,"<1",">1")) -> >1
B31: Tit. IV | C31: 8 | D31: 8 | E31: =IF(C31=D31,"=1",IF(C31<D31,"<1",">1")) -> =1
B32: Tit. V | C32: 12 | D32: 10 | E32: =IF(C32=D32,"=1",IF(C32<D32,"<1",">1")) -> >1
A33: SPESA | B33: Tit. I | C33: 12 | D33: 14 | E33: =IF(C33=D33,"=1",IF(C33<D33,"<1",">1")) -> <1
B34: Tit. II | C34: 3 | D34: 3 | E34: =IF(C34=D34,"=1",IF(C34<D34,"<1",">1")) -> =1
B35: Tit. III | C35: 5 | D35: 1 | E35: =IF(C35=D35,"=1",IF(C35<D35,"<1",">1")) -> >1
C37: Note:
C41: Indicatore G.4 | D41: Propensione all'investimento
C42: Indica la propensione dell'amministrazione locale ad investire in fattori pluriennali soggetti ad ammortamento (dalla realizzazione di infrastrutture alla acquisizione di beni).
C44: Spese in conto capitale | D44: numero abitanti | E44: G.4
C45: 1960000 | D45: 15520 | E45: =C45/D45 -> 126.28866
C47: Note:
C51: Indicatore G.5 | D51: Pressione tributaria per abitante
C52: Indica il benessere dell'amministrazione locale, in quanto permette di valutare il peso medio fiscale che i cittadini devono sopportare per permettere che l'amministrazione locale faccia fronte alle proprie spese di gestione.
C54: Entrate tributarie | D54: numero abitanti | E54: G.5
C55: =C7 -> 8683561.4 | D55: =D45 -> 15520 | E55: =C55/D55 -> 559.50782
C57: Note:
C61: Indicatore G.6 | D61: Rispetto del patto di stabilità
C62: Indica se l'amministrazione locale è in grado di tenere sotto controllo l'indebitamento netto definito come il saldo fra entrate e spese finali, al netto delle operazioni finanziarie (riscossione e concessioni crediti, partecipazioni e conferimenti, anticipazioni).
C64: Indicatore on/off
C65: SI
C67: Note:
C71: Indicatore G.7 | D71: Capacità di ascolto dei cittadini/utenti
C72: Permette di trasformare in valutazione quantitativa il parere soggettivo dei cittadini riguardo alla capacità della propria amministrazione locale di ascoltare le loro esigenze.
...

Sheet Operativi
A1: PROCESSI OPERATIVI
C3: Indicatore O.1 | D3: Rispetto dei tempi di rilascio dei documenti
C4: Misura l'efficacia del processo di rilascio dei documenti valutando il rispetto dei tempi di rilascio previsti. Effettua la misurazione con riferimento ad alcune tipologie di documenti rappresentative dell'insieme. La formula misura la media dell'indicatore "tempo rilascio eff.(te)/tempo rilascio previsto (tp)" calcolato per un panel di documenti "tipo", cioè : carta d'identità, certificati urbanistici, autorizzazione occupazione suolo pubblico, permesso di sosta per disabili.
C6: ∑ tempi effettivi di rilascio | D6: tempo previsto | E6: numero documenti emessi | F6: parziali | G6: O.1
A7: CI | C7: 24 | D7: 2 | E7: 10 | F7: =(C7+D7)/E7 -> 2.6 | G7: =(F7+F8+F9+F10)/4 -> 11.5
A8: CDU | C8: 200 | D8: 30 | E8: 10 | F8: =(C8+D8)/E8 -> 23
A9: AOSP | C9: 140 | D9: 15 | E9: 10 | F9: =(C9+D9)/E9 -> 15.5
A10: PD | C10: 19 | D10: 30 | E10: 10 | F10: =(C10+D10)/E10 -> 4.9
C12: Note:
C13: Periodo di riferimento: 3 mesi. C.I =Carte d'identità; CDU= Certificati di destinazione urbanistica; AOSP= Autorizzazioni occupazione suolo pubblico; PD=Permessi per disabili
C16: Indicatore O.2 | D16: Rispetto dei tempi di alcune pratiche tipo
C17: Misura la capacità dell'amministrazione locale di rispettare itempi di trattamento previsti. È indicatore di efficacia
C19: Media tempi effettivi di rilascio | D19: tempo previsto | E19: numero documenti emessi | F19: parziali | G19: O.2
A20: CR | C20: 2 | D20: 2 | E20: 10 | F20: =(C20+D20)/E20 -> 0.4 | G20: =(F20+F21+F22)/3 -> 3.6666667
A21: DIAP | C21: 28 | D21: 30 | E21: 10 | F21: =(C21+D21)/E21 -> 5.8
A22: SCIA | C22: 18 | D22: 30 | E22: 10 | F22: =(C22+D22)/E22 -> 4.8
C24: Note:
C25: Periodo di riferimento: 3 mesi. CR=Cambi di residenza; DIAP= Denuncia di inizio attività; SCIA= Segnalazione Certificata Inizio Attività
C28: Indicatore O.3 | D28: Accessibilità ai servizi
C29: Serve a valutare la disponibilità dell'amministrazione locale a mantenere accessibili al pubblico, in termini di orari di apertura, i servizi dotati di sportello.
C31: ∑ delle ore di apertura settimanali di tutti gli sportelli | D31: numero degli sportelli | E31: O.3
C32: =(5+5+10) -> 20 | D32: 3 | E32: =(C32/36)/D32 -> 0.18518519
C34: Note:
C35: Si riferisce al momento in cui viene fatta la misurazione
C38: Indicatore O.4 | D38: Assenza di barriere architettoniche
C39: Misura il livello di adeguamento dell'amministrazione locale ad un requisito previsto dalla legge.
C41: numero edifici attrezzati | D41: numero totale edifici | E41: O.4
C42: 4 | D42: 5 | E42: =C42/D42 -> 0.8
C44: Note:
C45: Si riferisce all'anno. I dati possono essere reperiti nel PEBA (Piano eliminazione barriere architettoniche)
C48: Indicatore O.5 | D48: Tempo medio di attesa allo sportello
C49: Misura l'efficacia del processo di erogazione dei servizi tramite sportello. Valuta la capacità dell'amministrazione locale di rispondere con tempestività alle richieste.
C51: ∑ tempi medi di attesa di ciascun sportello | D51: numero degli sportelli | E51: O.5
C52: =(5+10+30+5+20+2+8+15+5) -> 100 | D52: =D32 -> 3 | E52: =C52/D52 -> 33.333333
C54: Note:
C55: E' espresso in minuti. Si riferisce ad una misurazione effettuata 1 settimana al mese, per almeno 3 mesi consecutivi
C58: Indicatore O.6 | D58: Livello generale di soddisfazione dei cittadini
C59: Misura l'efficacia complessiva della macchina dell'amministrazione locale
C61: Risposta che ha ricevuto il maggior numero di "voti" opp. Media del livello di soddisfazione riferito ai singoli servizi | E61: O.6
C62: 4 | E62: =C62 -> 4
...

Sheet Supporto
A1: PROCESSI DI SUPPORTO
C3: Indicatore S.1 | D3: Tempo medio formazione atti interni (delibere, determine)
C4: Misura l'efficienza del processo di gestione degli atti interni con un focus sulle due tipologie di atti più rilevanti. Interessante è non soltanto il tempo medio necessario per la formazione dei due atti, ma anche il range (t.max-t.min) all'interno del quale si oscilla.
C6: ∑ tempi di formazione di ciascuna delibera | D6: numero di delibere | E6: ∑ tempi di formazione di ciascuna determina | F6: numero di determine | G6: S.1
C7: =(4*81)+(6*22) -> 456 | D7: =81+22 -> 103 | E7: =7*187 -> 1309 | F7: 187 | G7: =(C7/D7)+(E7/F7) -> 11.427184
C9: Note:
C10: Periodo di riferimento: 3 mesi. Tempo misurato in giorni. Il tempo è calcolato dal momento di inizio (bozza) alla formalizzazione dell'atto (pubblicazione), comprensivo delle eventuali interruzioni.
C13: Indicatore S.2 | D13: Rispetto tempi di emissione atti interni (delibere, determina)
C14: Misura l'efficacia del processo di gestione degli atti interni con un focus sulle due tipologie di atti più rilevanti.
C16: ∑ tempi rilascio effettivo di ogni delibera | D16: tempo di rilascio previsto per le delibere | E16: Numero di delibere | F16: S.2
C17: 456 | D17: 8 | E17: 103 | F17: =((C17/D17)/E17)+((C19/D19)/E19) -> 1.5533981
C18: ∑ tempi rilascio effettivo di ogni determina | D18: tempo di rilascio previsto per le determine | E18: Numero di determine
C19: 14 | D19: 7 | E19: 2
C21: Note:
C22: Periodo di riferimento: 3 mesi. Tempo misurato in giorni. Rapporto tra tempi da cui si ricava un valore assoluto
C25: Indicatore S.3 | D25: Funzionamento del protocollo in entrata
C26: Misura l'efficienza del processo di smistamento della posta in entrata, misurando il tempo medio di consegna agli uffici della posta proveniente dall'esterno
C28: ∑ tempo medio (gg) di consegna per ogni documento (data arrivo protocollo - data consegna ufficio) | D28: Numero documenti in entrata | E28: S.3
C29: 19987 | D29: 20951 | E29: =C29/D29 -> 0.95398788
C31: Note:
C32: Periodo di riferimento: 3 mesi. Tempo medio misurato in giorni.
C35: Indicatore S.4 | D35: Funzionamento del protocollo in uscita
C36: Misura l'efficienza del processo di spedizione della posta in uscita, misurando il tempo medio di spedizione della posta diretta all'esterno
C38: ∑ tempo medio (gg) di spedizione per ogni documento (data partenza dal protocollo - data documento) | D38: Numero documenti in uscita | E38: S.4
C39: 11187 | D39: 13967 | E39: =C39/D39 -> 0.8009594
C41: Note:
C42: Periodo di riferimento: 3 mesi. Tempo medio misurato in giorni.
C45: Indicatore S.5 | D45: Grado di dematerializzazione degli atti
C46: Misura l'impegno dell'amministrazione locale a procedere verso la completa sostituzione del proprio archivio cartaceo con un archivio informatico che permetta ai cittadini ed alle imprese di consultare gli atti amministrativi e conoscere lo stato di avanzamento dei propri procedimenti per via telematica.
C48: N.ro atti (delibere + determine + contratti) dematerializzati) | D48: Totale atti (delibere + determine + contratti) dematerializzati) | E48: S.5
C49: 20 | D49: =(456+1309+50) -> 1815 | E49: =C49/D49 -> 0.011019284
C51: Note:
C52: Periodo di riferimento: un anno.
C55: Indicatore S.6 | D55: Copertura dei servizi da parte di sistemi di monitoraggio della customer satisfaction
C56: Misura l'attenzione dell'amministrazione locale nei confronti della soddisfazione dei cittadini e la sua volontà di misurarsi per individuare punti di forza e aree da migliorare.
C58: Numero servizi coperti dalla CS | D58: Numero totale servizi | E58: S.6
C59: 2 | D59: 71 | E59: =C59/D59 -> 0.028169014
C61: Note:
C62: Si riferisce al questionario da riproporre 1 volta all'anno. Numero totale servizi = num. servizi totale ricavabile dall'elenco dei processi operativi
C65: Indicatore S.7 | D65: Livello di informatizzazione della struttura - Dotazioni PC, palmari, tablet
...

Sheet Totali
A2: N. | B2: Risultati
A3: G.1 | B3: =Governo!F7 -> 0.80856126
A4: G.2 | B4: =Governo!G17 -> 0.9
A5: G.3 | B5: =Governo!E28 -> >1 | C5: Tit. I | D5: ENTRATE
B6: =Governo!E29 -> <1 | C6: Tit. II
B7: =Governo!E30 -> >1 | C7: Tit. III
B8: =Governo!E31 -> =1 | C8: Tit. IV
B9: =Governo!E32 -> >1 | C9: Tit. V
B10: =Governo!E33 -> <1 | C10: Tit. I | D10: SPESA
B11: =Governo!E34 -> =1 | C11: Tit. II
B12: =Governo!E35 -> >1 | C12: Tit. III
A13: G.4 | B13: =Governo!E45 -> 126.28866
A14: G.5 | B14: =Governo!E55 -> 559.50782
A15: G.6 | B15: =Indicatore_on_off -> SI
A16: G.7 | B16: =Governo!C75 -> 5
A17: G.8 | B17: =Governo!D85 -> 0.66666667
A18: G.9 | B18: =Governo!E95 -> 0.5
A19: G.10 | B19: =Governo!E105 -> <1
A20: G.11 | B20: =Governo!E115 -> 0.25
A21: O.1 | B21: =Operativi!G7 -> 11.5
A22: O.2 | B22: =Operativi!G20 -> 3.6666667
A23: O.3 | B23: =Operativi!E32 -> 0.18518519
A24: O.4 | B24: =Operativi!E42 -> 0.8
A25: O.5 | B25: =Operativi!E52 -> 33.333333
A26: O.6 | B26: =Operativi!E62 -> 4
A27: O.7 | B27: =Operativi!F72 -> 0.9
A28: O.8 | B28: =Operativi!F82 -> 3
A29: O.9 | B29: =Operativi!E92 -> 0.9
A30: O.10 | B30: =Operativi!E102 -> 0.9375
A31: O.11 | B31: =Operativi!E112 -> 1
A32: O.12 | B32: =Operativi!E122 -> 3
A33: O.13 | B33: =Operativi!E132 -> 0.96069869
A34: O.14 | B34: =Operativi!E142 -> 0.00025773196
A35: O.15 | B35: =Operativi!E152 -> 0.00025773196
A36: O.16 | B36: =Operativi!E162 -> 0.51546392
A37: O.17 | B37: =Operativi!F172 -> 20.333333
A38: O.18 | B38: =Operativi!E182 -> 0.00096649485
A39: O.19 | B39: =Operativi!E192 -> 0.8
A40: O.20 | B40: =Operativi!E202 -> 0.75714286
A41: O.21 | B41: =Operativi!E212 -> 0.88
...

Sheet   
B3: SI
B4: NO
